Workbook

Sheet Wave Bending Moment
A1: IACS UR S11 — Vertical Wave Bending Moment
A2: Noah's Ark vs Panamax Bulk Carrier
A4: Formula: Mw = k · C · L² · B · (Cb + 0.7) × 10⁻³ [kN·m]
A5: k = 110 (hogging) | k = 190 (sagging) | C = wave coefficient = 10.75 − ((300−L)/100)^1.5 for 100 ≤ L ≤ 300m
A7: INPUTS
A8: Parameter | B8: Noah's Ark | C8: Panamax | D8: Notes
A9: Length L (m) | B9: 157.2 | C9: 225 | D9: Ark: 300 × 0.524m | Panamax: typical
A10: Beam B (m) | B10: 26.2 | C10: 32.2 | D10: Ark: 50 × 0.524m | Panamax: typical
A11: Block coefficient Cb | B11: 0.87 | C11: 0.83 | D11: Ark: CAD AR-003-20110418 | Panamax: typical
A12: Draft T (m) | B12: 7.86 | C12: 14 | D12: Ark: 15 cubits (Gen 7:20) | Panamax: typical
A13: Wave coefficient C | B13: =10.75-((300-B9)/100)^1.5 -> 9.0435549 | C13: =10.75-((300-C9)/100)^1.5 -> 10.100481 | D13: IACS UR S11 — valid 100 ≤ L ≤ 300m
A15: RESULTS
B16: Noah's Ark | C16: Panamax | D16: Notes
A17: Mw Hogging (kN·m) | B17: =110*B13*B9^2*B10*(B11+0.7)*0.001 -> 1011201.9 | C17: =110*C13*C9^2*C10*(C11+0.7)*0.001 -> 2771067.3 | D17: k=110
A18: Mw Sagging (kN·m) | B18: =190*B13*B9^2*B10*(B11+0.7)*0.001 -> 1746621.5 | C18: =190*C13*C9^2*C10*(C11+0.7)*0.001 -> 4786389 | D18: k=190
A19: Mw Hogging (MN·m) | B19: =B17/1000 -> 1011.2019 | C19: =C17/1000 -> 2771.0673
A20: Mw Sagging (MN·m) | B20: =B18/1000 -> 1746.6215 | C20: =C18/1000 -> 4786.389
A22: Source: IACS Unified Requirement S11 (Rev.7, 2022). Blue cells = inputs (edit freely).

Sheet Wave Shear Force
A1: IACS UR S11 — Vertical Wave Shear Force
A2: Noah's Ark vs Panamax Bulk Carrier
A4: Formula: Vw = k · C · L · B · (Cb + 0.7) × 10⁻² [kN]
A5: k = 30 (positive/hogging shear) | k = 37 (negative/sagging shear) | C = wave coefficient (same as WBM sheet)
A6: Maximum shear occurs at approx. quarter-length points — governs hull wall, bulkhead connections, and frame sizing at L/4.
A8: INPUTS (linked from Wave Bending Moment sheet)
A9: Parameter | B9: Noah's Ark | C9: Panamax | D9: Notes
A10: Length L (m) | B10: ='Wave Bending Moment'!B9 -> 157.2 | C10: ='Wave Bending Moment'!C9 -> 225 | D10: ='Wave Bending Moment'!D9 -> Ark: 300 × 0.524m | Panamax: typical
A11: Beam B (m) | B11: ='Wave Bending Moment'!B10 -> 26.2 | C11: ='Wave Bending Moment'!C10 -> 32.2 | D11: ='Wave Bending Moment'!D10 -> Ark: 50 × 0.524m | Panamax: typical
A12: Block coefficient Cb | B12: ='Wave Bending Moment'!B11 -> 0.87 | C12: ='Wave Bending Moment'!C11 -> 0.83 | D12: ='Wave Bending Moment'!D11 -> Ark: CAD AR-003-20110418 | Panamax: typical
A13: Wave coefficient C | B13: ='Wave Bending Moment'!B13 -> 9.0435549 | C13: ='Wave Bending Moment'!C13 -> 10.100481 | D13: ='Wave Bending Moment'!D13 -> IACS UR S11 — valid 100 ≤ L ≤ 300m
A15: RESULTS
B16: Noah's Ark | C16: Panamax | D16: Notes
A17: Vw Positive/Hogging (kN) | B17: =30*B13*B10*B11*(B12+0.7)*0.01 -> 17543.406 | C17: =30*C13*C10*C11*(C12+0.7)*0.01 -> 33588.695 | D17: k=30
A18: Vw Negative/Sagging (kN) | B18: =37*B13*B10*B11*(B12+0.7)*0.01 -> 21636.868 | C18: =37*C13*C10*C11*(C12+0.7)*0.01 -> 41426.057 | D18: k=37
A19: Vw Positive/Hogging (MN) | B19: =B17/1000 -> 17.543406 | C19: =C17/1000 -> 33.588695
A20: Vw Negative/Sagging (MN) | B20: =B18/1000 -> 21.636868 | C20: =C18/1000 -> 41.426057
A22: Source: IACS UR S11 (Rev.7, 2022). Green cells = linked from WBM sheet — edit inputs there.

Sheet Longitudinal Shear
A1: Longitudinal Shear Flow — Hull Box Section
A2: Noah's Ark — thin-walled box beam approximation
A4: Formula: q = VQ/I [kN/m] where V = vertical shear, Q = first moment of area above shear plane, I = second moment of area
A5: Critical planes: (1) deck-to-side joint (2) keel-to-side joint (3) neutral axis (mid-height)
A7: INPUTS — Hull Cross Section
A8: Parameter | B8: Value | C8: Units | D8: Notes
A9: Overall depth D (m) | B9: 15.72 | C9: m | D9: 30 cubits × 0.524m
A10: Overall beam B (m) | B10: 26.2 | C10: m | D10: 50 cubits × 0.524m
A11: Wall thickness t (m) | B11: 0.939 | C11: m | D11: 127mm plank + 812mm frame — all walls equal
A12: Shear force V (kN) | B12: ='Wave Shear Force'!B18 -> 21636.868 | C12: kN | D12: Linked — sagging (governing) from shear sheet
A14: SECTION PROPERTIES
A15: Property | B15: Formula result | C15: Units | D15: Notes
A16: Second moment of area I (m⁴) | B16: =(1/12)*B10*B9^3-(1/12)*(B10-2*B11)*(B9-2*B11)^3 -> 3106.1509 | C16: m⁴ | D16: Outer box minus inner void
A17: Q at deck joint (m³) | B17: =B10*B11*(B9/2-B11/2) -> 181.8196 | C17: m³ | D17: Top flange contribution only
A18: Q at neutral axis (m³) | B18: =B10*B11*(B9/2-B11/2)+2*B11*(B9/2-B11)*(B9/4-B11/2) -> 226.79793 | C18: m³ | D18: Top flange + half webs
A20: SHEAR FLOW RESULTS
A21: Location | B21: Shear flow q (kN/m) | C21: Stress τ (MPa) | D21: Notes
A22: Deck-to-side joint | B22: =B12*B17/B16 -> 1266.5215 | C22: =B12*B17/B16/(2*B11)/1000 -> 0.67439907 | D22: q split between 2 joints; τ = q/(2t)
A23: Keel-to-side joint | B23: =B12*B17/B16 -> 1266.5215 | C23: =B12*B17/B16/(2*B11)/1000 -> 0.67439907 | D23: Same as deck by symmetry
A24: Neutral axis (max shear flow) | B24: =B12*B18/B16 -> 1579.8321 | C24: =B12*B18/B16/(2*B11)/1000 -> 0.84123114 | D24: Shared by 2 webs — divide by 2
A26: Timber shear capacity reference: parallel to grain 6–12 MPa | perpendicular (rolling) shear 1.5–3 MPa | old growth pine ~8 MPa parallel
A27: Source: IACS UR S11 (Rev.7, 2022). Blue = input, green = linked from Wave Shear Force sheet.

Sheet GZ Curve
A1: GZ Restoring Arm — Rectangular Cross Section (Hong eq. 11–14)
A2: All hull forms in this study had a rectangular cross section — Hong et al. (1994)
A4: INPUTS
A5: Parameter | B5: Value | C5: Units | D5: Notes
A6: Beam B₀ (m) | B6: 26.2 | C6: m | D6: 50 cubits × 0.524m — edit freely
A7: Depth D (m) | B7: 15.72 | C7: m | D7: 30 cubits × 0.524m
A8: Draft d₀ (m) | B8: 7.86 | C8: m | D8: 15 cubits — Genesis 7:20
A9: KG (m) | B9: 9.52 | C9: m | D9: Under review — edit freely
A10: Seawater density ρ | B10: 1.025 | C10: t/m³
A11: Angle step (deg) | B11: 2 | C11: ° | D11: Resolution of GZ curve
A13: DERIVED
A14: Freeboard f (m) | B14: =B7-B8 -> 7.86 | C14: m | D14: D - d₀
A15: OG (m) | B15: =B8-B9 -> -1.66 | C15: m | D15: d₀ - KG (eq.13) — negative means G above waterline
A16: Deck corner angle φ_max | B16: =DEGREES(ATAN(2*(B7-B8)/B6)) -> 30.963757 | C16: ° | D16: Heel at which deck edge submerges
A17: Displacement Δ (t/m run) | B17: =B6*B8*B10 -> 211.0803 | C17: t/m | D17: Per unit length — buoyancy force constant
A18: GM₀ (m) | B18: =B6^2/(12*B8)-(B9-B8/2) -> 1.6877778 | C18: m | D18: BM - KG + KB = B²/12d - KG + d/2
A20: GZ CURVE — Hong equations 11–14 (rectangular cross section)
A21: Heel φ (°) | B21: OB (m) | C21: KB (m) | D21: GZ (m) | E21: Notes
A22: =B11*0 -> 0 | B22: =(B6^2*TAN(RADIANS(B11*0)))/(12*B8) -> 0 | C22: =(0.5*(B8-B6/2*TAN(RADIANS(B11*0)))^2*B6)/(B6*B8)+(B6^3*TAN(RADIANS(B11*0))^2*(B8-B6/2*TAN(RADIANS(B11*0))))/(6*B6*B8) -> 3.93 | D22: =B22*COS(RADIANS(B11*0))+B15*SIN(RADIANS(B11*0))-(B8-C22)*SIN(RADIANS(B11*0)) -> 0 | E22: ""
A23: =B11*1 -> 2 | B23: =(B6^2*TAN(RADIANS(B11*1)))/(12*B8) -> 0.2541456 | C23: =(0.5*(B8-B6/2*TAN(RADIANS(B11*1)))^2*B6)/(B6*B8)+(B6^3*TAN(RADIANS(B11*1))^2*(B8-B6/2*TAN(RADIANS(B11*1))))/(6*B6*B8) -> 3.6172448 | D23: =B23*COS(RADIANS(B11*1))+B15*SIN(RADIANS(B11*1))-(B8-C23)*SIN(RADIANS(B11*1)) -> 0.047987596 | E23: =IF(B11*1>B16,"⚠ beyond deck edge","")
A24: =B11*2 -> 4 | B24: =(B6^2*TAN(RADIANS(B11*2)))/(12*B8) -> 0.5089118 | C24: =(0.5*(B8-B6/2*TAN(RADIANS(B11*2)))^2*B6)/(B6*B8)+(B6^3*TAN(RADIANS(B11*2))^2*(B8-B6/2*TAN(RADIANS(B11*2))))/(6*B6*B8) -> 3.5615621 | D24: =B24*COS(RADIANS(B11*2))+B15*SIN(RADIANS(B11*2))-(B8-C24)*SIN(RADIANS(B11*2)) -> 0.092032499 | E24: =IF(B11*2>B16,"⚠ beyond deck edge","")
A25: =B11*3 -> 6 | B25: =(B6^2*TAN(RADIANS(B11*3)))/(12*B8) -> 0.76492527 | C25: =(0.5*(B8-B6/2*TAN(RADIANS(B11*3)))^2*B6)/(B6*B8)+(B6^3*TAN(RADIANS(B11*3))^2*(B8-B6/2*TAN(RADIANS(B11*3))))/(6*B6*B8) -> 3.7161775 | D25: =B25*COS(RADIANS(B11*3))+B15*SIN(RADIANS(B11*3))-(B8-C25)*SIN(RADIANS(B11*3)) -> 0.15407028 | E25: =IF(B11*3>B16,"⚠ beyond deck edge","")
A26: =B11*4 -> 8 | B26: =(B6^2*TAN(RADIANS(B11*4)))/(12*B8) -> 1.022825 | C26: =(0.5*(B8-B6/2*TAN(RADIANS(B11*4)))^2*B6)/(B6*B8)+(B6^3*TAN(RADIANS(B11*4))^2*(B8-B6/2*TAN(RADIANS(B11*4))))/(6*B6*B8) -> 4.0349602 | D26: =B26*COS(RADIANS(B11*4))+B15*SIN(RADIANS(B11*4))-(B8-C26)*SIN(RADIANS(B11*4)) -> 0.2495009 | E26: =IF(B11*4>B16,"⚠ beyond deck edge","")
A27: =B11*5 -> 10 | B27: =(B6^2*TAN(RADIANS(B11*5)))/(12*B8) -> 1.2832686 | C27: =(0.5*(B8-B6/2*TAN(RADIANS(B11*5)))^2*B6)/(B6*B8)+(B6^3*TAN(RADIANS(B11*5))^2*(B8-B6/2*TAN(RADIANS(B11*5))))/(6*B6*B8) -> 4.4712327 | D27: =B27*COS(RADIANS(B11*5))+B15*SIN(RADIANS(B11*5))-(B8-C27)*SIN(RADIANS(B11*5)) -> 0.38706361 | E27: =IF(B11*5>B16,"⚠ beyond deck edge","")
A28: =B11*6 -> 12 | B28: =(B6^2*TAN(RADIANS(B11*6)))/(12*B8) -> 1.5469394 | C28: =(0.5*(B8-B6/2*TAN(RADIANS(B11*6)))^2*B6)/(B6*B8)+(B6^3*TAN(RADIANS(B11*6))^2*(B8-B6/2*TAN(RADIANS(B11*6))))/(6*B6*B8) -> 4.9765051 | D28: =B28*COS(RADIANS(B11*6))+B15*SIN(RADIANS(B11*6))-(B8-C28)*SIN(RADIANS(B11*6)) -> 0.56848937 | E28: =IF(B11*6>B16,"⚠ beyond deck edge","")
A29: =B11*7 -> 14 | B29: =(B6^2*TAN(RADIANS(B11*7)))/(12*B8) -> 1.8145538 | C29: =(0.5*(B8-B6/2*TAN(RADIANS(B11*7)))^2*B6)/(B6*B8)+(B6^3*TAN(RADIANS(B11*7))^2*(B8-B6/2*TAN(RADIANS(B11*7))))/(6*B6*B8) -> 5.4990801 | D29: =B29*COS(RADIANS(B11*7))+B15*SIN(RADIANS(B11*7))-(B8-C29)*SIN(RADIANS(B11*7)) -> 0.78790524 | E29: =IF(B11*7>B16,"⚠ beyond deck edge","")
A30: =B11*8 -> 16 | B30: =(B6^2*TAN(RADIANS(B11*8)))/(12*B8) -> 2.0868692 | C30: =(0.5*(B8-B6/2*TAN(RADIANS(B11*8)))^2*B6)/(B6*B8)+(B6^3*TAN(RADIANS(B11*8))^2*(B8-B6/2*TAN(RADIANS(B11*8))))/(6*B6*B8) -> 5.9824674 | D30: =B30*COS(RADIANS(B11*8))+B15*SIN(RADIANS(B11*8))-(B8-C30)*SIN(RADIANS(B11*8)) -> 1.0309513 | E30: =IF(B11*8>B16,"⚠ beyond deck edge","")
A31: =B11*9 -> 18 | B31: =(B6^2*TAN(RADIANS(B11*9)))/(12*B8) -> 2.3646933 | C31: =(0.5*(B8-B6/2*TAN(RADIANS(B11*9)))^2*B6)/(B6*B8)+(B6^3*TAN(RADIANS(B11*9))^2*(B8-B6/2*TAN(RADIANS(B11*9))))/(6*B6*B8) -> 6.3635286 | D31: =B31*COS(RADIANS(B11*9))+B15*SIN(RADIANS(B11*9))-(B8-C31)*SIN(RADIANS(B11*9)) -> 1.2735537 | E31: =IF(B11*9>B16,"⚠ beyond deck edge","")
A32: =B11*10 -> 20 | B32: =(B6^2*TAN(RADIANS(B11*10)))/(12*B8) -> 2.6488945 | C32: =(0.5*(B8-B6/2*TAN(RADIANS(B11*10)))^2*B6)/(B6*B8)+(B6^3*TAN(RADIANS(B11*10))^2*(B8-B6/2*TAN(RADIANS(B11*10))))/(6*B6*B8) -> 6.570259 | D32: =B32*COS(RADIANS(B11*10))+B15*SIN(RADIANS(B11*10))-(B8-C32)*SIN(RADIANS(B11*10)) -> 1.4802757 | E32: =IF(B11*10>B16,"⚠ beyond deck edge","")
A33: =B11*11 -> 22 | B33: =(B6^2*TAN(RADIANS(B11*11)))/(12*B8) -> 2.9404131 | C33: =(0.5*(B8-B6/2*TAN(RADIANS(B11*11)))^2*B6)/(B6*B8)+(B6^3*TAN(RADIANS(B11*11))^2*(B8-B6/2*TAN(RADIANS(B11*11))))/(6*B6*B8) -> 6.5190843 | D33: =B33*COS(RADIANS(B11*11))+B15*SIN(RADIANS(B11*11))-(B8-C33)*SIN(RADIANS(B11*11)) -> 1.6021407 | E33: =IF(B11*11>B16,"⚠ beyond deck edge","")
A34: =B11*12 -> 24 | B34: =(B6^2*TAN(RADIANS(B11*12)))/(12*B8) -> 3.2402754 | C34: =(0.5*(B8-B6/2*TAN(RADIANS(B11*12)))^2*B6)/(B6*B8)+(B6^3*TAN(RADIANS(B11*12))^2*(B8-B6/2*TAN(RADIANS(B11*12))))/(6*B6*B8) -> 6.1115125 | D34: =B34*COS(RADIANS(B11*12))+B15*SIN(RADIANS(B11*12))-(B8-C34)*SIN(RADIANS(B11*12)) -> 1.5737822 | E34: =IF(B11*12>B16,"⚠ beyond deck edge","")
A35: =B11*13 -> 26 | B35: =(B6^2*TAN(RADIANS(B11*13)))/(12*B8) -> 3.5496094 | C35: =(0.5*(B8-B6/2*TAN(RADIANS(B11*13)))^2*B6)/(B6*B8)+(B6^3*TAN(RADIANS(B11*13))^2*(B8-B6/2*TAN(RADIANS(B11*13))))/(6*B6*B8) -> 5.2299327 | D35: =B35*COS(RADIANS(B11*13))+B15*SIN(RADIANS(B11*13))-(B8-C35)*SIN(RADIANS(B11*13)) -> 1.3097261 | E35: =IF(B11*13>B16,"⚠ beyond deck edge","")
A36: =B11*14 -> 28 | B36: =(B6^2*TAN(RADIANS(B11*14)))/(12*B8) -> 3.8696631 | C36: =(0.5*(B8-B6/2*TAN(RADIANS(B11*14)))^2*B6)/(B6*B8)+(B6^3*TAN(RADIANS(B11*14))^2*(B8-B6/2*TAN(RADIANS(B11*14))))/(6*B6*B8) -> 3.7322816 | D36: =B36*COS(RADIANS(B11*14))+B15*SIN(RADIANS(B11*14))-(B8-C36)*SIN(RADIANS(B11*14)) -> 0.69954049 | E36: =IF(B11*14>B16,"⚠ beyond deck edge","")
A37: =B11*15 -> 30 | B37: =(B6^2*TAN(RADIANS(B11*15)))/(12*B8) -> 4.201827 | C37: =(0.5*(B8-B6/2*TAN(RADIANS(B11*15)))^2*B6)/(B6*B8)+(B6^3*TAN(RADIANS(B11*15))^2*(B8-B6/2*TAN(RADIANS(B11*15))))/(6*B6*B8) -> 1.4452005 | D37: =B37*COS(RADIANS(B11*15))+B15*SIN(RADIANS(B11*15))-(B8-C37)*SIN(RADIANS(B11*15)) -> -0.39851087 | E37: =IF(B11*15>B16,"⚠ beyond deck edge","")
A38: =B11*16 -> 32 | B38: =(B6^2*TAN(RADIANS(B11*16)))/(12*B8) -> 4.5476603 | C38: =(0.5*(B8-B6/2*TAN(RADIANS(B11*16)))^2*B6)/(B6*B8)+(B6^3*TAN(RADIANS(B11*16))^2*(B8-B6/2*TAN(RADIANS(B11*16))))/(6*B6*B8) -> -1.8448304 | D38: =B38*COS(RADIANS(B11*16))+B15*SIN(RADIANS(B11*16))-(B8-C38)*SIN(RADIANS(B11*16)) -> -2.1658079 | E38: =IF(B11*16>B16,"⚠ beyond deck edge","") -> ⚠ beyond deck edge
A39: =B11*17 -> 34 | B39: =(B6^2*TAN(RADIANS(B11*17)))/(12*B8) -> 4.9089231 | C39: =(0.5*(B8-B6/2*TAN(RADIANS(B11*17)))^2*B6)/(B6*B8)+(B6^3*TAN(RADIANS(B11*17))^2*(B8-B6/2*TAN(RADIANS(B11*17))))/(6*B6*B8) -> -6.4030912 | D39: =B39*COS(RADIANS(B11*17))+B15*SIN(RADIANS(B11*17))-(B8-C39)*SIN(RADIANS(B11*17)) -> -4.8343979 | E39: =IF(B11*17>B16,"⚠ beyond deck edge","") -> ⚠ beyond deck edge
A40: =B11*18 -> 36 | B40: =(B6^2*TAN(RADIANS(B11*18)))/(12*B8) -> 5.2876151 | C40: =(0.5*(B8-B6/2*TAN(RADIANS(B11*18)))^2*B6)/(B6*B8)+(B6^3*TAN(RADIANS(B11*18))^2*(B8-B6/2*TAN(RADIANS(B11*18))))/(6*B6*B8) -> -12.561943 | D40: =B40*COS(RADIANS(B11*18))+B15*SIN(RADIANS(B11*18))-(B8-C40)*SIN(RADIANS(B11*18)) -> -8.7016698 | E40: =IF(B11*18>B16,"⚠ beyond deck edge","") -> ⚠ beyond deck edge
A41: =B11*19 -> 38 | B41: =(B6^2*TAN(RADIANS(B11*19)))/(12*B8) -> 5.6860232 | C41: =(0.5*(B8-B6/2*TAN(RADIANS(B11*19)))^2*B6)/(B6*B8)+(B6^3*TAN(RADIANS(B11*19))^2*(B8-B6/2*TAN(RADIANS(B11*19))))/(6*B6*B8) -> -20.741262 | D41: =B41*COS(RADIANS(B11*19))+B15*SIN(RADIANS(B11*19))-(B8-C41)*SIN(RADIANS(B11*19)) -> -14.150046 | E41: =IF(B11*19>B16,"⚠ beyond deck edge","") -> ⚠ beyond deck edge
A42: =B11*20 -> 40 | B42: =(B6^2*TAN(RADIANS(B11*20)))/(12*B8) -> 6.1067806 | C42: =(0.5*(B8-B6/2*TAN(RADIANS(B11*20)))^2*B6)/(B6*B8)+(B6^3*TAN(RADIANS(B11*20))^2*(B8-B6/2*TAN(RADIANS(B11*20))))/(6*B6*B8) -> -31.475984 | D42: =B42*COS(RADIANS(B11*20))+B15*SIN(RADIANS(B11*20))-(B8-C42)*SIN(RADIANS(B11*20)) -> -21.673645 | E42: =IF(B11*20>B16,"⚠ beyond deck edge","") -> ⚠ beyond deck edge
A43: =B11*21 -> 42 | B43: =(B6^2*TAN(RADIANS(B11*21)))/(12*B8) -> 6.5529405 | C43: =(0.5*(B8-B6/2*TAN(RADIANS(B11*21)))^2*B6)/(B6*B8)+(B6^3*TAN(RADIANS(B11*21))^2*(B8-B6/2*TAN(RADIANS(B11*21))))/(6*B6*B8) -> -45.453624 | D43: =B43*COS(RADIANS(B11*21))+B15*SIN(RADIANS(B11*21))-(B8-C43)*SIN(RADIANS(B11*21)) -> -31.914751 | E43: =IF(B11*21>B16,"⚠ beyond deck edge","") -> ⚠ beyond deck edge
...
