Workbook

Sheet Inputs
A1: JONSWAP Fetch-Limited Wave Height Calculator
A2: Hasselmann et al. (1973) / USACE Coastal Engineering Manual
A3: Noah's Ark Naval Architecture Research — T. Lovett
A5: Formula
A6: Fetch-limited: gHs/U² = 0.0016 · (gF/U²)^0.5
A7: Fully developed: gHs/U² = 0.243 (cap)
A8: U = wind speed at 10m height (m/s), F = fetch (m), g = 9.81 m/s²
A10: Constants (blue = input — change these to explore)
A11: g (m/s²) | B11: 9.81 | C11: Gravitational acceleration
A12: Growth coefficient | B12: 0.0016 | C12: JONSWAP Hasselmann et al. 1973
A13: Fully-developed limit gHs/U² | B13: 0.243 | C13: JONSWAP fully-developed cap
A15: Wind Speeds (blue = input)
A16: Wind speed 20 kn (m/s) | B16: 10.2888 | C16: 20 knots x 0.51444
A17: Wind speed 30 kn (m/s) | B17: 15.4332 | C17: 30 knots x 0.51444
A18: Wind speed 40 kn (m/s) | B18: 20.5776 | C18: 40 knots x 0.51444
A19: Wind speed 50 kn (m/s) | B19: 25.722 | C19: 50 knots x 0.51444
A21: Fetch range
A22: Start (km) | B22: 0
A23: End (km) | B23: 2000
A24: Step (km) | B24: 50
A26: Colour key:
A27: Blue = hardcoded input | Green = formula referencing Inputs | Black = label

Sheet Data
A1: Fetch (km) | B1: Hs 20 kn (m) | C1: Hs 30 kn (m) | D1: Hs 40 kn (m) | E1: Hs 50 kn (m)
A2: =Inputs!$B$22+0*Inputs!$B$24 -> 0 | B2: =IF(A2=0,0,MIN(Inputs!$B$13,Inputs!$B$12*SQRT(Inputs!$B$11*A2*1000/(Inputs!$B$16^2)))*Inputs!$B$16^2/Inputs!$B$11) -> 0 | C2: =IF(A2=0,0,MIN(Inputs!$B$13,Inputs!$B$12*SQRT(Inputs!$B$11*A2*1000/(Inputs!$B$17^2)))*Inputs!$B$17^2/Inputs!$B$11) -> 0 | D2: =IF(A2=0,0,MIN(Inputs!$B$13,Inputs!$B$12*SQRT(Inputs!$B$11*A2*1000/(Inputs!$B$18^2)))*Inputs!$B$18^2/Inputs!$B$11) -> 0 | E2: =IF(A2=0,0,MIN(Inputs!$B$13,Inputs!$B$12*SQRT(Inputs!$B$11*A2*1000/(Inputs!$B$19^2)))*Inputs!$B$19^2/Inputs!$B$11) -> 0
A3: =Inputs!$B$22+1*Inputs!$B$24 -> 50 | B3: =IF(A3=0,0,MIN(Inputs!$B$13,Inputs!$B$12*SQRT(Inputs!$B$11*A3*1000/(Inputs!$B$16^2)))*Inputs!$B$16^2/Inputs!$B$11) -> 1.1752634 | C3: =IF(A3=0,0,MIN(Inputs!$B$13,Inputs!$B$12*SQRT(Inputs!$B$11*A3*1000/(Inputs!$B$17^2)))*Inputs!$B$17^2/Inputs!$B$11) -> 1.7628951 | D3: =IF(A3=0,0,MIN(Inputs!$B$13,Inputs!$B$12*SQRT(Inputs!$B$11*A3*1000/(Inputs!$B$18^2)))*Inputs!$B$18^2/Inputs!$B$11) -> 2.3505268 | E3: =IF(A3=0,0,MIN(Inputs!$B$13,Inputs!$B$12*SQRT(Inputs!$B$11*A3*1000/(Inputs!$B$19^2)))*Inputs!$B$19^2/Inputs!$B$11) -> 2.9381585
A4: =Inputs!$B$22+2*Inputs!$B$24 -> 100 | B4: =IF(A4=0,0,MIN(Inputs!$B$13,Inputs!$B$12*SQRT(Inputs!$B$11*A4*1000/(Inputs!$B$16^2)))*Inputs!$B$16^2/Inputs!$B$11) -> 1.6620734 | C4: =IF(A4=0,0,MIN(Inputs!$B$13,Inputs!$B$12*SQRT(Inputs!$B$11*A4*1000/(Inputs!$B$17^2)))*Inputs!$B$17^2/Inputs!$B$11) -> 2.4931101 | D4: =IF(A4=0,0,MIN(Inputs!$B$13,Inputs!$B$12*SQRT(Inputs!$B$11*A4*1000/(Inputs!$B$18^2)))*Inputs!$B$18^2/Inputs!$B$11) -> 3.3241468 | E4: =IF(A4=0,0,MIN(Inputs!$B$13,Inputs!$B$12*SQRT(Inputs!$B$11*A4*1000/(Inputs!$B$19^2)))*Inputs!$B$19^2/Inputs!$B$11) -> 4.1551835
A5: =Inputs!$B$22+3*Inputs!$B$24 -> 150 | B5: =IF(A5=0,0,MIN(Inputs!$B$13,Inputs!$B$12*SQRT(Inputs!$B$11*A5*1000/(Inputs!$B$16^2)))*Inputs!$B$16^2/Inputs!$B$11) -> 2.0356159 | C5: =IF(A5=0,0,MIN(Inputs!$B$13,Inputs!$B$12*SQRT(Inputs!$B$11*A5*1000/(Inputs!$B$17^2)))*Inputs!$B$17^2/Inputs!$B$11) -> 3.0534238 | D5: =IF(A5=0,0,MIN(Inputs!$B$13,Inputs!$B$12*SQRT(Inputs!$B$11*A5*1000/(Inputs!$B$18^2)))*Inputs!$B$18^2/Inputs!$B$11) -> 4.0712318 | E5: =IF(A5=0,0,MIN(Inputs!$B$13,Inputs!$B$12*SQRT(Inputs!$B$11*A5*1000/(Inputs!$B$19^2)))*Inputs!$B$19^2/Inputs!$B$11) -> 5.0890397
A6: =Inputs!$B$22+4*Inputs!$B$24 -> 200 | B6: =IF(A6=0,0,MIN(Inputs!$B$13,Inputs!$B$12*SQRT(Inputs!$B$11*A6*1000/(Inputs!$B$16^2)))*Inputs!$B$16^2/Inputs!$B$11) -> 2.3505268 | C6: =IF(A6=0,0,MIN(Inputs!$B$13,Inputs!$B$12*SQRT(Inputs!$B$11*A6*1000/(Inputs!$B$17^2)))*Inputs!$B$17^2/Inputs!$B$11) -> 3.5257902 | D6: =IF(A6=0,0,MIN(Inputs!$B$13,Inputs!$B$12*SQRT(Inputs!$B$11*A6*1000/(Inputs!$B$18^2)))*Inputs!$B$18^2/Inputs!$B$11) -> 4.7010535 | E6: =IF(A6=0,0,MIN(Inputs!$B$13,Inputs!$B$12*SQRT(Inputs!$B$11*A6*1000/(Inputs!$B$19^2)))*Inputs!$B$19^2/Inputs!$B$11) -> 5.8763169
A7: =Inputs!$B$22+5*Inputs!$B$24 -> 250 | B7: =IF(A7=0,0,MIN(Inputs!$B$13,Inputs!$B$12*SQRT(Inputs!$B$11*A7*1000/(Inputs!$B$16^2)))*Inputs!$B$16^2/Inputs!$B$11) -> 2.6222055 | C7: =IF(A7=0,0,MIN(Inputs!$B$13,Inputs!$B$12*SQRT(Inputs!$B$11*A7*1000/(Inputs!$B$17^2)))*Inputs!$B$17^2/Inputs!$B$11) -> 3.9419532 | D7: =IF(A7=0,0,MIN(Inputs!$B$13,Inputs!$B$12*SQRT(Inputs!$B$11*A7*1000/(Inputs!$B$18^2)))*Inputs!$B$18^2/Inputs!$B$11) -> 5.2559376 | E7: =IF(A7=0,0,MIN(Inputs!$B$13,Inputs!$B$12*SQRT(Inputs!$B$11*A7*1000/(Inputs!$B$19^2)))*Inputs!$B$19^2/Inputs!$B$11) -> 6.5699221
A8: =Inputs!$B$22+6*Inputs!$B$24 -> 300 | B8: =IF(A8=0,0,MIN(Inputs!$B$13,Inputs!$B$12*SQRT(Inputs!$B$11*A8*1000/(Inputs!$B$16^2)))*Inputs!$B$16^2/Inputs!$B$11) -> 2.6222055 | C8: =IF(A8=0,0,MIN(Inputs!$B$13,Inputs!$B$12*SQRT(Inputs!$B$11*A8*1000/(Inputs!$B$17^2)))*Inputs!$B$17^2/Inputs!$B$11) -> 4.3181934 | D8: =IF(A8=0,0,MIN(Inputs!$B$13,Inputs!$B$12*SQRT(Inputs!$B$11*A8*1000/(Inputs!$B$18^2)))*Inputs!$B$18^2/Inputs!$B$11) -> 5.7575912 | E8: =IF(A8=0,0,MIN(Inputs!$B$13,Inputs!$B$12*SQRT(Inputs!$B$11*A8*1000/(Inputs!$B$19^2)))*Inputs!$B$19^2/Inputs!$B$11) -> 7.196989
A9: =Inputs!$B$22+7*Inputs!$B$24 -> 350 | B9: =IF(A9=0,0,MIN(Inputs!$B$13,Inputs!$B$12*SQRT(Inputs!$B$11*A9*1000/(Inputs!$B$16^2)))*Inputs!$B$16^2/Inputs!$B$11) -> 2.6222055 | C9: =IF(A9=0,0,MIN(Inputs!$B$13,Inputs!$B$12*SQRT(Inputs!$B$11*A9*1000/(Inputs!$B$17^2)))*Inputs!$B$17^2/Inputs!$B$11) -> 4.664182 | D9: =IF(A9=0,0,MIN(Inputs!$B$13,Inputs!$B$12*SQRT(Inputs!$B$11*A9*1000/(Inputs!$B$18^2)))*Inputs!$B$18^2/Inputs!$B$11) -> 6.2189093 | E9: =IF(A9=0,0,MIN(Inputs!$B$13,Inputs!$B$12*SQRT(Inputs!$B$11*A9*1000/(Inputs!$B$19^2)))*Inputs!$B$19^2/Inputs!$B$11) -> 7.7736366
A10: =Inputs!$B$22+8*Inputs!$B$24 -> 400 | B10: =IF(A10=0,0,MIN(Inputs!$B$13,Inputs!$B$12*SQRT(Inputs!$B$11*A10*1000/(Inputs!$B$16^2)))*Inputs!$B$16^2/Inputs!$B$11) -> 2.6222055 | C10: =IF(A10=0,0,MIN(Inputs!$B$13,Inputs!$B$12*SQRT(Inputs!$B$11*A10*1000/(Inputs!$B$17^2)))*Inputs!$B$17^2/Inputs!$B$11) -> 4.9862203 | D10: =IF(A10=0,0,MIN(Inputs!$B$13,Inputs!$B$12*SQRT(Inputs!$B$11*A10*1000/(Inputs!$B$18^2)))*Inputs!$B$18^2/Inputs!$B$11) -> 6.6482937 | E10: =IF(A10=0,0,MIN(Inputs!$B$13,Inputs!$B$12*SQRT(Inputs!$B$11*A10*1000/(Inputs!$B$19^2)))*Inputs!$B$19^2/Inputs!$B$11) -> 8.3103671
A11: =Inputs!$B$22+9*Inputs!$B$24 -> 450 | B11: =IF(A11=0,0,MIN(Inputs!$B$13,Inputs!$B$12*SQRT(Inputs!$B$11*A11*1000/(Inputs!$B$16^2)))*Inputs!$B$16^2/Inputs!$B$11) -> 2.6222055 | C11: =IF(A11=0,0,MIN(Inputs!$B$13,Inputs!$B$12*SQRT(Inputs!$B$11*A11*1000/(Inputs!$B$17^2)))*Inputs!$B$17^2/Inputs!$B$11) -> 5.2886852 | D11: =IF(A11=0,0,MIN(Inputs!$B$13,Inputs!$B$12*SQRT(Inputs!$B$11*A11*1000/(Inputs!$B$18^2)))*Inputs!$B$18^2/Inputs!$B$11) -> 7.0515803 | E11: =IF(A11=0,0,MIN(Inputs!$B$13,Inputs!$B$12*SQRT(Inputs!$B$11*A11*1000/(Inputs!$B$19^2)))*Inputs!$B$19^2/Inputs!$B$11) -> 8.8144754
A12: =Inputs!$B$22+10*Inputs!$B$24 -> 500 | B12: =IF(A12=0,0,MIN(Inputs!$B$13,Inputs!$B$12*SQRT(Inputs!$B$11*A12*1000/(Inputs!$B$16^2)))*Inputs!$B$16^2/Inputs!$B$11) -> 2.6222055 | C12: =IF(A12=0,0,MIN(Inputs!$B$13,Inputs!$B$12*SQRT(Inputs!$B$11*A12*1000/(Inputs!$B$17^2)))*Inputs!$B$17^2/Inputs!$B$11) -> 5.5747637 | D12: =IF(A12=0,0,MIN(Inputs!$B$13,Inputs!$B$12*SQRT(Inputs!$B$11*A12*1000/(Inputs!$B$18^2)))*Inputs!$B$18^2/Inputs!$B$11) -> 7.4330183 | E12: =IF(A12=0,0,MIN(Inputs!$B$13,Inputs!$B$12*SQRT(Inputs!$B$11*A12*1000/(Inputs!$B$19^2)))*Inputs!$B$19^2/Inputs!$B$11) -> 9.2912729
A13: =Inputs!$B$22+11*Inputs!$B$24 -> 550 | B13: =IF(A13=0,0,MIN(Inputs!$B$13,Inputs!$B$12*SQRT(Inputs!$B$11*A13*1000/(Inputs!$B$16^2)))*Inputs!$B$16^2/Inputs!$B$11) -> 2.6222055 | C13: =IF(A13=0,0,MIN(Inputs!$B$13,Inputs!$B$12*SQRT(Inputs!$B$11*A13*1000/(Inputs!$B$17^2)))*Inputs!$B$17^2/Inputs!$B$11) -> 5.8468615 | D13: =IF(A13=0,0,MIN(Inputs!$B$13,Inputs!$B$12*SQRT(Inputs!$B$11*A13*1000/(Inputs!$B$18^2)))*Inputs!$B$18^2/Inputs!$B$11) -> 7.7958154 | E13: =IF(A13=0,0,MIN(Inputs!$B$13,Inputs!$B$12*SQRT(Inputs!$B$11*A13*1000/(Inputs!$B$19^2)))*Inputs!$B$19^2/Inputs!$B$11) -> 9.7447692
A14: =Inputs!$B$22+12*Inputs!$B$24 -> 600 | B14: =IF(A14=0,0,MIN(Inputs!$B$13,Inputs!$B$12*SQRT(Inputs!$B$11*A14*1000/(Inputs!$B$16^2)))*Inputs!$B$16^2/Inputs!$B$11) -> 2.6222055 | C14: =IF(A14=0,0,MIN(Inputs!$B$13,Inputs!$B$12*SQRT(Inputs!$B$11*A14*1000/(Inputs!$B$17^2)))*Inputs!$B$17^2/Inputs!$B$11) -> 5.8999623 | D14: =IF(A14=0,0,MIN(Inputs!$B$13,Inputs!$B$12*SQRT(Inputs!$B$11*A14*1000/(Inputs!$B$18^2)))*Inputs!$B$18^2/Inputs!$B$11) -> 8.1424636 | E14: =IF(A14=0,0,MIN(Inputs!$B$13,Inputs!$B$12*SQRT(Inputs!$B$11*A14*1000/(Inputs!$B$19^2)))*Inputs!$B$19^2/Inputs!$B$11) -> 10.178079
A15: =Inputs!$B$22+13*Inputs!$B$24 -> 650 | B15: =IF(A15=0,0,MIN(Inputs!$B$13,Inputs!$B$12*SQRT(Inputs!$B$11*A15*1000/(Inputs!$B$16^2)))*Inputs!$B$16^2/Inputs!$B$11) -> 2.6222055 | C15: =IF(A15=0,0,MIN(Inputs!$B$13,Inputs!$B$12*SQRT(Inputs!$B$11*A15*1000/(Inputs!$B$17^2)))*Inputs!$B$17^2/Inputs!$B$11) -> 5.8999623 | D15: =IF(A15=0,0,MIN(Inputs!$B$13,Inputs!$B$12*SQRT(Inputs!$B$11*A15*1000/(Inputs!$B$18^2)))*Inputs!$B$18^2/Inputs!$B$11) -> 8.4749448 | E15: =IF(A15=0,0,MIN(Inputs!$B$13,Inputs!$B$12*SQRT(Inputs!$B$11*A15*1000/(Inputs!$B$19^2)))*Inputs!$B$19^2/Inputs!$B$11) -> 10.593681
A16: =Inputs!$B$22+14*Inputs!$B$24 -> 700 | B16: =IF(A16=0,0,MIN(Inputs!$B$13,Inputs!$B$12*SQRT(Inputs!$B$11*A16*1000/(Inputs!$B$16^2)))*Inputs!$B$16^2/Inputs!$B$11) -> 2.6222055 | C16: =IF(A16=0,0,MIN(Inputs!$B$13,Inputs!$B$12*SQRT(Inputs!$B$11*A16*1000/(Inputs!$B$17^2)))*Inputs!$B$17^2/Inputs!$B$11) -> 5.8999623 | D16: =IF(A16=0,0,MIN(Inputs!$B$13,Inputs!$B$12*SQRT(Inputs!$B$11*A16*1000/(Inputs!$B$18^2)))*Inputs!$B$18^2/Inputs!$B$11) -> 8.7948659 | E16: =IF(A16=0,0,MIN(Inputs!$B$13,Inputs!$B$12*SQRT(Inputs!$B$11*A16*1000/(Inputs!$B$19^2)))*Inputs!$B$19^2/Inputs!$B$11) -> 10.993582
A17: =Inputs!$B$22+15*Inputs!$B$24 -> 750 | B17: =IF(A17=0,0,MIN(Inputs!$B$13,Inputs!$B$12*SQRT(Inputs!$B$11*A17*1000/(Inputs!$B$16^2)))*Inputs!$B$16^2/Inputs!$B$11) -> 2.6222055 | C17: =IF(A17=0,0,MIN(Inputs!$B$13,Inputs!$B$12*SQRT(Inputs!$B$11*A17*1000/(Inputs!$B$17^2)))*Inputs!$B$17^2/Inputs!$B$11) -> 5.8999623 | D17: =IF(A17=0,0,MIN(Inputs!$B$13,Inputs!$B$12*SQRT(Inputs!$B$11*A17*1000/(Inputs!$B$18^2)))*Inputs!$B$18^2/Inputs!$B$11) -> 9.103551 | E17: =IF(A17=0,0,MIN(Inputs!$B$13,Inputs!$B$12*SQRT(Inputs!$B$11*A17*1000/(Inputs!$B$19^2)))*Inputs!$B$19^2/Inputs!$B$11) -> 11.379439
A18: =Inputs!$B$22+16*Inputs!$B$24 -> 800 | B18: =IF(A18=0,0,MIN(Inputs!$B$13,Inputs!$B$12*SQRT(Inputs!$B$11*A18*1000/(Inputs!$B$16^2)))*Inputs!$B$16^2/Inputs!$B$11) -> 2.6222055 | C18: =IF(A18=0,0,MIN(Inputs!$B$13,Inputs!$B$12*SQRT(Inputs!$B$11*A18*1000/(Inputs!$B$17^2)))*Inputs!$B$17^2/Inputs!$B$11) -> 5.8999623 | D18: =IF(A18=0,0,MIN(Inputs!$B$13,Inputs!$B$12*SQRT(Inputs!$B$11*A18*1000/(Inputs!$B$18^2)))*Inputs!$B$18^2/Inputs!$B$11) -> 9.4021071 | E18: =IF(A18=0,0,MIN(Inputs!$B$13,Inputs!$B$12*SQRT(Inputs!$B$11*A18*1000/(Inputs!$B$19^2)))*Inputs!$B$19^2/Inputs!$B$11) -> 11.752634
A19: =Inputs!$B$22+17*Inputs!$B$24 -> 850 | B19: =IF(A19=0,0,MIN(Inputs!$B$13,Inputs!$B$12*SQRT(Inputs!$B$11*A19*1000/(Inputs!$B$16^2)))*Inputs!$B$16^2/Inputs!$B$11) -> 2.6222055 | C19: =IF(A19=0,0,MIN(Inputs!$B$13,Inputs!$B$12*SQRT(Inputs!$B$11*A19*1000/(Inputs!$B$17^2)))*Inputs!$B$17^2/Inputs!$B$11) -> 5.8999623 | D19: =IF(A19=0,0,MIN(Inputs!$B$13,Inputs!$B$12*SQRT(Inputs!$B$11*A19*1000/(Inputs!$B$18^2)))*Inputs!$B$18^2/Inputs!$B$11) -> 9.6914702 | E19: =IF(A19=0,0,MIN(Inputs!$B$13,Inputs!$B$12*SQRT(Inputs!$B$11*A19*1000/(Inputs!$B$19^2)))*Inputs!$B$19^2/Inputs!$B$11) -> 12.114338
A20: =Inputs!$B$22+18*Inputs!$B$24 -> 900 | B20: =IF(A20=0,0,MIN(Inputs!$B$13,Inputs!$B$12*SQRT(Inputs!$B$11*A20*1000/(Inputs!$B$16^2)))*Inputs!$B$16^2/Inputs!$B$11) -> 2.6222055 | C20: =IF(A20=0,0,MIN(Inputs!$B$13,Inputs!$B$12*SQRT(Inputs!$B$11*A20*1000/(Inputs!$B$17^2)))*Inputs!$B$17^2/Inputs!$B$11) -> 5.8999623 | D20: =IF(A20=0,0,MIN(Inputs!$B$13,Inputs!$B$12*SQRT(Inputs!$B$11*A20*1000/(Inputs!$B$18^2)))*Inputs!$B$18^2/Inputs!$B$11) -> 9.9724405 | E20: =IF(A20=0,0,MIN(Inputs!$B$13,Inputs!$B$12*SQRT(Inputs!$B$11*A20*1000/(Inputs!$B$19^2)))*Inputs!$B$19^2/Inputs!$B$11) -> 12.465551
A21: =Inputs!$B$22+19*Inputs!$B$24 -> 950 | B21: =IF(A21=0,0,MIN(Inputs!$B$13,Inputs!$B$12*SQRT(Inputs!$B$11*A21*1000/(Inputs!$B$16^2)))*Inputs!$B$16^2/Inputs!$B$11) -> 2.6222055 | C21: =IF(A21=0,0,MIN(Inputs!$B$13,Inputs!$B$12*SQRT(Inputs!$B$11*A21*1000/(Inputs!$B$17^2)))*Inputs!$B$17^2/Inputs!$B$11) -> 5.8999623 | D21: =IF(A21=0,0,MIN(Inputs!$B$13,Inputs!$B$12*SQRT(Inputs!$B$11*A21*1000/(Inputs!$B$18^2)))*Inputs!$B$18^2/Inputs!$B$11) -> 10.245709 | E21: =IF(A21=0,0,MIN(Inputs!$B$13,Inputs!$B$12*SQRT(Inputs!$B$11*A21*1000/(Inputs!$B$19^2)))*Inputs!$B$19^2/Inputs!$B$11) -> 12.807136
A22: =Inputs!$B$22+20*Inputs!$B$24 -> 1000 | B22: =IF(A22=0,0,MIN(Inputs!$B$13,Inputs!$B$12*SQRT(Inputs!$B$11*A22*1000/(Inputs!$B$16^2)))*Inputs!$B$16^2/Inputs!$B$11) -> 2.6222055 | C22: =IF(A22=0,0,MIN(Inputs!$B$13,Inputs!$B$12*SQRT(Inputs!$B$11*A22*1000/(Inputs!$B$17^2)))*Inputs!$B$17^2/Inputs!$B$11) -> 5.8999623 | D22: =IF(A22=0,0,MIN(Inputs!$B$13,Inputs!$B$12*SQRT(Inputs!$B$11*A22*1000/(Inputs!$B$18^2)))*Inputs!$B$18^2/Inputs!$B$11) -> 10.488822 | E22: =IF(A22=0,0,MIN(Inputs!$B$13,Inputs!$B$12*SQRT(Inputs!$B$11*A22*1000/(Inputs!$B$19^2)))*Inputs!$B$19^2/Inputs!$B$11) -> 13.139844
A23: =Inputs!$B$22+21*Inputs!$B$24 -> 1050 | B23: =IF(A23=0,0,MIN(Inputs!$B$13,Inputs!$B$12*SQRT(Inputs!$B$11*A23*1000/(Inputs!$B$16^2)))*Inputs!$B$16^2/Inputs!$B$11) -> 2.6222055 | C23: =IF(A23=0,0,MIN(Inputs!$B$13,Inputs!$B$12*SQRT(Inputs!$B$11*A23*1000/(Inputs!$B$17^2)))*Inputs!$B$17^2/Inputs!$B$11) -> 5.8999623 | D23: =IF(A23=0,0,MIN(Inputs!$B$13,Inputs!$B$12*SQRT(Inputs!$B$11*A23*1000/(Inputs!$B$18^2)))*Inputs!$B$18^2/Inputs!$B$11) -> 10.488822 | E23: =IF(A23=0,0,MIN(Inputs!$B$13,Inputs!$B$12*SQRT(Inputs!$B$11*A23*1000/(Inputs!$B$19^2)))*Inputs!$B$19^2/Inputs!$B$11) -> 13.464334
A24: =Inputs!$B$22+22*Inputs!$B$24 -> 1100 | B24: =IF(A24=0,0,MIN(Inputs!$B$13,Inputs!$B$12*SQRT(Inputs!$B$11*A24*1000/(Inputs!$B$16^2)))*Inputs!$B$16^2/Inputs!$B$11) -> 2.6222055 | C24: =IF(A24=0,0,MIN(Inputs!$B$13,Inputs!$B$12*SQRT(Inputs!$B$11*A24*1000/(Inputs!$B$17^2)))*Inputs!$B$17^2/Inputs!$B$11) -> 5.8999623 | D24: =IF(A24=0,0,MIN(Inputs!$B$13,Inputs!$B$12*SQRT(Inputs!$B$11*A24*1000/(Inputs!$B$18^2)))*Inputs!$B$18^2/Inputs!$B$11) -> 10.488822 | E24: =IF(A24=0,0,MIN(Inputs!$B$13,Inputs!$B$12*SQRT(Inputs!$B$11*A24*1000/(Inputs!$B$19^2)))*Inputs!$B$19^2/Inputs!$B$11) -> 13.781185
A25: =Inputs!$B$22+23*Inputs!$B$24 -> 1150 | B25: =IF(A25=0,0,MIN(Inputs!$B$13,Inputs!$B$12*SQRT(Inputs!$B$11*A25*1000/(Inputs!$B$16^2)))*Inputs!$B$16^2/Inputs!$B$11) -> 2.6222055 | C25: =IF(A25=0,0,MIN(Inputs!$B$13,Inputs!$B$12*SQRT(Inputs!$B$11*A25*1000/(Inputs!$B$17^2)))*Inputs!$B$17^2/Inputs!$B$11) -> 5.8999623 | D25: =IF(A25=0,0,MIN(Inputs!$B$13,Inputs!$B$12*SQRT(Inputs!$B$11*A25*1000/(Inputs!$B$18^2)))*Inputs!$B$18^2/Inputs!$B$11) -> 10.488822 | E25: =IF(A25=0,0,MIN(Inputs!$B$13,Inputs!$B$12*SQRT(Inputs!$B$11*A25*1000/(Inputs!$B$19^2)))*Inputs!$B$19^2/Inputs!$B$11) -> 14.090913
A26: =Inputs!$B$22+24*Inputs!$B$24 -> 1200 | B26: =IF(A26=0,0,MIN(Inputs!$B$13,Inputs!$B$12*SQRT(Inputs!$B$11*A26*1000/(Inputs!$B$16^2)))*Inputs!$B$16^2/Inputs!$B$11) -> 2.6222055 | C26: =IF(A26=0,0,MIN(Inputs!$B$13,Inputs!$B$12*SQRT(Inputs!$B$11*A26*1000/(Inputs!$B$17^2)))*Inputs!$B$17^2/Inputs!$B$11) -> 5.8999623 | D26: =IF(A26=0,0,MIN(Inputs!$B$13,Inputs!$B$12*SQRT(Inputs!$B$11*A26*1000/(Inputs!$B$18^2)))*Inputs!$B$18^2/Inputs!$B$11) -> 10.488822 | E26: =IF(A26=0,0,MIN(Inputs!$B$13,Inputs!$B$12*SQRT(Inputs!$B$11*A26*1000/(Inputs!$B$19^2)))*Inputs!$B$19^2/Inputs!$B$11) -> 14.393978
A27: =Inputs!$B$22+25*Inputs!$B$24 -> 1250 | B27: =IF(A27=0,0,MIN(Inputs!$B$13,Inputs!$B$12*SQRT(Inputs!$B$11*A27*1000/(Inputs!$B$16^2)))*Inputs!$B$16^2/Inputs!$B$11) -> 2.6222055 | C27: =IF(A27=0,0,MIN(Inputs!$B$13,Inputs!$B$12*SQRT(Inputs!$B$11*A27*1000/(Inputs!$B$17^2)))*Inputs!$B$17^2/Inputs!$B$11) -> 5.8999623 | D27: =IF(A27=0,0,MIN(Inputs!$B$13,Inputs!$B$12*SQRT(Inputs!$B$11*A27*1000/(Inputs!$B$18^2)))*Inputs!$B$18^2/Inputs!$B$11) -> 10.488822 | E27: =IF(A27=0,0,MIN(Inputs!$B$13,Inputs!$B$12*SQRT(Inputs!$B$11*A27*1000/(Inputs!$B$19^2)))*Inputs!$B$19^2/Inputs!$B$11) -> 14.690792
A28: =Inputs!$B$22+26*Inputs!$B$24 -> 1300 | B28: =IF(A28=0,0,MIN(Inputs!$B$13,Inputs!$B$12*SQRT(Inputs!$B$11*A28*1000/(Inputs!$B$16^2)))*Inputs!$B$16^2/Inputs!$B$11) -> 2.6222055 | C28: =IF(A28=0,0,MIN(Inputs!$B$13,Inputs!$B$12*SQRT(Inputs!$B$11*A28*1000/(Inputs!$B$17^2)))*Inputs!$B$17^2/Inputs!$B$11) -> 5.8999623 | D28: =IF(A28=0,0,MIN(Inputs!$B$13,Inputs!$B$12*SQRT(Inputs!$B$11*A28*1000/(Inputs!$B$18^2)))*Inputs!$B$18^2/Inputs!$B$11) -> 10.488822 | E28: =IF(A28=0,0,MIN(Inputs!$B$13,Inputs!$B$12*SQRT(Inputs!$B$11*A28*1000/(Inputs!$B$19^2)))*Inputs!$B$19^2/Inputs!$B$11) -> 14.981727
A29: =Inputs!$B$22+27*Inputs!$B$24 -> 1350 | B29: =IF(A29=0,0,MIN(Inputs!$B$13,Inputs!$B$12*SQRT(Inputs!$B$11*A29*1000/(Inputs!$B$16^2)))*Inputs!$B$16^2/Inputs!$B$11) -> 2.6222055 | C29: =IF(A29=0,0,MIN(Inputs!$B$13,Inputs!$B$12*SQRT(Inputs!$B$11*A29*1000/(Inputs!$B$17^2)))*Inputs!$B$17^2/Inputs!$B$11) -> 5.8999623 | D29: =IF(A29=0,0,MIN(Inputs!$B$13,Inputs!$B$12*SQRT(Inputs!$B$11*A29*1000/(Inputs!$B$18^2)))*Inputs!$B$18^2/Inputs!$B$11) -> 10.488822 | E29: =IF(A29=0,0,MIN(Inputs!$B$13,Inputs!$B$12*SQRT(Inputs!$B$11*A29*1000/(Inputs!$B$19^2)))*Inputs!$B$19^2/Inputs!$B$11) -> 15.267119
A30: =Inputs!$B$22+28*Inputs!$B$24 -> 1400 | B30: =IF(A30=0,0,MIN(Inputs!$B$13,Inputs!$B$12*SQRT(Inputs!$B$11*A30*1000/(Inputs!$B$16^2)))*Inputs!$B$16^2/Inputs!$B$11) -> 2.6222055 | C30: =IF(A30=0,0,MIN(Inputs!$B$13,Inputs!$B$12*SQRT(Inputs!$B$11*A30*1000/(Inputs!$B$17^2)))*Inputs!$B$17^2/Inputs!$B$11) -> 5.8999623 | D30: =IF(A30=0,0,MIN(Inputs!$B$13,Inputs!$B$12*SQRT(Inputs!$B$11*A30*1000/(Inputs!$B$18^2)))*Inputs!$B$18^2/Inputs!$B$11) -> 10.488822 | E30: =IF(A30=0,0,MIN(Inputs!$B$13,Inputs!$B$12*SQRT(Inputs!$B$11*A30*1000/(Inputs!$B$19^2)))*Inputs!$B$19^2/Inputs!$B$11) -> 15.547273
A31: =Inputs!$B$22+29*Inputs!$B$24 -> 1450 | B31: =IF(A31=0,0,MIN(Inputs!$B$13,Inputs!$B$12*SQRT(Inputs!$B$11*A31*1000/(Inputs!$B$16^2)))*Inputs!$B$16^2/Inputs!$B$11) -> 2.6222055 | C31: =IF(A31=0,0,MIN(Inputs!$B$13,Inputs!$B$12*SQRT(Inputs!$B$11*A31*1000/(Inputs!$B$17^2)))*Inputs!$B$17^2/Inputs!$B$11) -> 5.8999623 | D31: =IF(A31=0,0,MIN(Inputs!$B$13,Inputs!$B$12*SQRT(Inputs!$B$11*A31*1000/(Inputs!$B$18^2)))*Inputs!$B$18^2/Inputs!$B$11) -> 10.488822 | E31: =IF(A31=0,0,MIN(Inputs!$B$13,Inputs!$B$12*SQRT(Inputs!$B$11*A31*1000/(Inputs!$B$19^2)))*Inputs!$B$19^2/Inputs!$B$11) -> 15.822468
A32: =Inputs!$B$22+30*Inputs!$B$24 -> 1500 | B32: =IF(A32=0,0,MIN(Inputs!$B$13,Inputs!$B$12*SQRT(Inputs!$B$11*A32*1000/(Inputs!$B$16^2)))*Inputs!$B$16^2/Inputs!$B$11) -> 2.6222055 | C32: =IF(A32=0,0,MIN(Inputs!$B$13,Inputs!$B$12*SQRT(Inputs!$B$11*A32*1000/(Inputs!$B$17^2)))*Inputs!$B$17^2/Inputs!$B$11) -> 5.8999623 | D32: =IF(A32=0,0,MIN(Inputs!$B$13,Inputs!$B$12*SQRT(Inputs!$B$11*A32*1000/(Inputs!$B$18^2)))*Inputs!$B$18^2/Inputs!$B$11) -> 10.488822 | E32: =IF(A32=0,0,MIN(Inputs!$B$13,Inputs!$B$12*SQRT(Inputs!$B$11*A32*1000/(Inputs!$B$19^2)))*Inputs!$B$19^2/Inputs!$B$11) -> 16.092957
A33: =Inputs!$B$22+31*Inputs!$B$24 -> 1550 | B33: =IF(A33=0,0,MIN(Inputs!$B$13,Inputs!$B$12*SQRT(Inputs!$B$11*A33*1000/(Inputs!$B$16^2)))*Inputs!$B$16^2/Inputs!$B$11) -> 2.6222055 | C33: =IF(A33=0,0,MIN(Inputs!$B$13,Inputs!$B$12*SQRT(Inputs!$B$11*A33*1000/(Inputs!$B$17^2)))*Inputs!$B$17^2/Inputs!$B$11) -> 5.8999623 | D33: =IF(A33=0,0,MIN(Inputs!$B$13,Inputs!$B$12*SQRT(Inputs!$B$11*A33*1000/(Inputs!$B$18^2)))*Inputs!$B$18^2/Inputs!$B$11) -> 10.488822 | E33: =IF(A33=0,0,MIN(Inputs!$B$13,Inputs!$B$12*SQRT(Inputs!$B$11*A33*1000/(Inputs!$B$19^2)))*Inputs!$B$19^2/Inputs!$B$11) -> 16.358974
A34: =Inputs!$B$22+32*Inputs!$B$24 -> 1600 | B34: =IF(A34=0,0,MIN(Inputs!$B$13,Inputs!$B$12*SQRT(Inputs!$B$11*A34*1000/(Inputs!$B$16^2)))*Inputs!$B$16^2/Inputs!$B$11) -> 2.6222055 | C34: =IF(A34=0,0,MIN(Inputs!$B$13,Inputs!$B$12*SQRT(Inputs!$B$11*A34*1000/(Inputs!$B$17^2)))*Inputs!$B$17^2/Inputs!$B$11) -> 5.8999623 | D34: =IF(A34=0,0,MIN(Inputs!$B$13,Inputs!$B$12*SQRT(Inputs!$B$11*A34*1000/(Inputs!$B$18^2)))*Inputs!$B$18^2/Inputs!$B$11) -> 10.488822 | E34: =IF(A34=0,0,MIN(Inputs!$B$13,Inputs!$B$12*SQRT(Inputs!$B$11*A34*1000/(Inputs!$B$19^2)))*Inputs!$B$19^2/Inputs!$B$11) -> 16.388784
A35: =Inputs!$B$22+33*Inputs!$B$24 -> 1650 | B35: =IF(A35=0,0,MIN(Inputs!$B$13,Inputs!$B$12*SQRT(Inputs!$B$11*A35*1000/(Inputs!$B$16^2)))*Inputs!$B$16^2/Inputs!$B$11) -> 2.6222055 | C35: =IF(A35=0,0,MIN(Inputs!$B$13,Inputs!$B$12*SQRT(Inputs!$B$11*A35*1000/(Inputs!$B$17^2)))*Inputs!$B$17^2/Inputs!$B$11) -> 5.8999623 | D35: =IF(A35=0,0,MIN(Inputs!$B$13,Inputs!$B$12*SQRT(Inputs!$B$11*A35*1000/(Inputs!$B$18^2)))*Inputs!$B$18^2/Inputs!$B$11) -> 10.488822 | E35: =IF(A35=0,0,MIN(Inputs!$B$13,Inputs!$B$12*SQRT(Inputs!$B$11*A35*1000/(Inputs!$B$19^2)))*Inputs!$B$19^2/Inputs!$B$11) -> 16.388784
A36: =Inputs!$B$22+34*Inputs!$B$24 -> 1700 | B36: =IF(A36=0,0,MIN(Inputs!$B$13,Inputs!$B$12*SQRT(Inputs!$B$11*A36*1000/(Inputs!$B$16^2)))*Inputs!$B$16^2/Inputs!$B$11) -> 2.6222055 | C36: =IF(A36=0,0,MIN(Inputs!$B$13,Inputs!$B$12*SQRT(Inputs!$B$11*A36*1000/(Inputs!$B$17^2)))*Inputs!$B$17^2/Inputs!$B$11) -> 5.8999623 | D36: =IF(A36=0,0,MIN(Inputs!$B$13,Inputs!$B$12*SQRT(Inputs!$B$11*A36*1000/(Inputs!$B$18^2)))*Inputs!$B$18^2/Inputs!$B$11) -> 10.488822 | E36: =IF(A36=0,0,MIN(Inputs!$B$13,Inputs!$B$12*SQRT(Inputs!$B$11*A36*1000/(Inputs!$B$19^2)))*Inputs!$B$19^2/Inputs!$B$11) -> 16.388784
A37: =Inputs!$B$22+35*Inputs!$B$24 -> 1750 | B37: =IF(A37=0,0,MIN(Inputs!$B$13,Inputs!$B$12*SQRT(Inputs!$B$11*A37*1000/(Inputs!$B$16^2)))*Inputs!$B$16^2/Inputs!$B$11) -> 2.6222055 | C37: =IF(A37=0,0,MIN(Inputs!$B$13,Inputs!$B$12*SQRT(Inputs!$B$11*A37*1000/(Inputs!$B$17^2)))*Inputs!$B$17^2/Inputs!$B$11) -> 5.8999623 | D37: =IF(A37=0,0,MIN(Inputs!$B$13,Inputs!$B$12*SQRT(Inputs!$B$11*A37*1000/(Inputs!$B$18^2)))*Inputs!$B$18^2/Inputs!$B$11) -> 10.488822 | E37: =IF(A37=0,0,MIN(Inputs!$B$13,Inputs!$B$12*SQRT(Inputs!$B$11*A37*1000/(Inputs!$B$19^2)))*Inputs!$B$19^2/Inputs!$B$11) -> 16.388784
A38: =Inputs!$B$22+36*Inputs!$B$24 -> 1800 | B38: =IF(A38=0,0,MIN(Inputs!$B$13,Inputs!$B$12*SQRT(Inputs!$B$11*A38*1000/(Inputs!$B$16^2)))*Inputs!$B$16^2/Inputs!$B$11) -> 2.6222055 | C38: =IF(A38=0,0,MIN(Inputs!$B$13,Inputs!$B$12*SQRT(Inputs!$B$11*A38*1000/(Inputs!$B$17^2)))*Inputs!$B$17^2/Inputs!$B$11) -> 5.8999623 | D38: =IF(A38=0,0,MIN(Inputs!$B$13,Inputs!$B$12*SQRT(Inputs!$B$11*A38*1000/(Inputs!$B$18^2)))*Inputs!$B$18^2/Inputs!$B$11) -> 10.488822 | E38: =IF(A38=0,0,MIN(Inputs!$B$13,Inputs!$B$12*SQRT(Inputs!$B$11*A38*1000/(Inputs!$B$19^2)))*Inputs!$B$19^2/Inputs!$B$11) -> 16.388784
A39: =Inputs!$B$22+37*Inputs!$B$24 -> 1850 | B39: =IF(A39=0,0,MIN(Inputs!$B$13,Inputs!$B$12*SQRT(Inputs!$B$11*A39*1000/(Inputs!$B$16^2)))*Inputs!$B$16^2/Inputs!$B$11) -> 2.6222055 | C39: =IF(A39=0,0,MIN(Inputs!$B$13,Inputs!$B$12*SQRT(Inputs!$B$11*A39*1000/(Inputs!$B$17^2)))*Inputs!$B$17^2/Inputs!$B$11) -> 5.8999623 | D39: =IF(A39=0,0,MIN(Inputs!$B$13,Inputs!$B$12*SQRT(Inputs!$B$11*A39*1000/(Inputs!$B$18^2)))*Inputs!$B$18^2/Inputs!$B$11) -> 10.488822 | E39: =IF(A39=0,0,MIN(Inputs!$B$13,Inputs!$B$12*SQRT(Inputs!$B$11*A39*1000/(Inputs!$B$19^2)))*Inputs!$B$19^2/Inputs!$B$11) -> 16.388784
A40: =Inputs!$B$22+38*Inputs!$B$24 -> 1900 | B40: =IF(A40=0,0,MIN(Inputs!$B$13,Inputs!$B$12*SQRT(Inputs!$B$11*A40*1000/(Inputs!$B$16^2)))*Inputs!$B$16^2/Inputs!$B$11) -> 2.6222055 | C40: =IF(A40=0,0,MIN(Inputs!$B$13,Inputs!$B$12*SQRT(Inputs!$B$11*A40*1000/(Inputs!$B$17^2)))*Inputs!$B$17^2/Inputs!$B$11) -> 5.8999623 | D40: =IF(A40=0,0,MIN(Inputs!$B$13,Inputs!$B$12*SQRT(Inputs!$B$11*A40*1000/(Inputs!$B$18^2)))*Inputs!$B$18^2/Inputs!$B$11) -> 10.488822 | E40: =IF(A40=0,0,MIN(Inputs!$B$13,Inputs!$B$12*SQRT(Inputs!$B$11*A40*1000/(Inputs!$B$19^2)))*Inputs!$B$19^2/Inputs!$B$11) -> 16.388784
...

Sheet Chart
A1: JONSWAP Fetch vs Significant Wave Height
A2: Hasselmann et al. (1973) — Noah's Ark Naval Architecture Research — T. Lovett
A3: Change wind speeds or fetch range on the Inputs sheet — chart updates automatically.
